<?xml version="1.0"?>
<!--

  Copyright (c) 2011-2012, PAL Robotics, S.L.
  All rights reserved.

  This work is licensed under the Creative Commons Attribution-NonCommercial-NoDerivs 3.0 Unported License.
  To view a copy of this license, visit http://creativecommons.org/licenses/by-nc-nd/3.0/ or send a letter to
  Creative Commons, 444 Castro Street, Suite 900, Mountain View, California, 94041, USA.
-->
<robot xmlns:xacro="http://ros.org/wiki/xacro">

  <!--File includes-->
  <xacro:include filename="$(find reemc_description)/urdf/deg_to_rad.xacro" />
  <xacro:include filename="$(find reemc_description)/urdf/head/head.transmission.xacro" />
  <xacro:include filename="$(find reemc_description)/urdf/sensors/range.urdf.xacro" />

  <!--Constant parameters-->
  <xacro:property name="head_friction" value="1.0" />
  <xacro:property name="head_damping"  value="0.5" />
  <xacro:property name="head_max_vel"  value="3.0" />
  <xacro:property name="head_eps"      value="0.02" />

  <!--************************-->
  <!--     HEAD_1 (PAN)       -->
  <!--************************-->
  <xacro:macro name="reem_head_1" params="name parent">
    <link name="${name}_link">
      <inertial>
        <origin xyz="0.014823 -0.000253 -0.008383" rpy="0 0 0" />
        <mass value="0.646763" />
        <!-- NOTE: Assuming cylinder with r=0.06, h=0.08 -->
<!--         <inertia ixx="0.0014125"  ixy="0"  ixz="0" iyy="0.0014125" iyz="0" izz="0.0017738" /> -->
        <inertia ixx="0.001175"  ixy="-0.000003"  ixz="0.000012" iyy="0.001273" iyz="-0.000008" izz="0.001132" />
      </inertial>
      <visual>
        <origin rpy="0 0 0" xyz="-0.03 0 0"/> <!--TODO: Remove offset when good meshes arrive-->
        <geometry>
          <mesh filename="package://reemc_description/meshes/head/head_1.dae" />
        </geometry>
        <material name="DarkGrey" />
      </visual>
      <collision>
        <origin xyz="-0.03 0 0" rpy="0 0 0" />
        <geometry>
          <mesh filename="package://reemc_description/meshes/head/head_1_collision.stl" />
        </geometry>
      </collision>
    </link>

    <joint name="${name}_joint" type="revolute">
      <parent link="${parent}"/>
      <child link="${name}_link"/>
      <origin xyz="0.0 -0.42316 0" rpy="${90.0 * deg_to_rad} 0 0" />
      <axis xyz="0 0 1" />
      <limit lower="${-75.0 * deg_to_rad}" upper="${75.0 * deg_to_rad}" effort="3.4" velocity="${head_max_vel}" />
      <dynamics damping="${head_damping}" friction="${head_friction}"/>

      <safety_controller k_position="20"
                         k_velocity="20"
                         soft_lower_limit="${-73.0 * deg_to_rad + head_eps}"
                         soft_upper_limit="${ 73.0 * deg_to_rad - head_eps}" />
    </joint>

    <gazebo reference="${name}_link">
      <mu1>0.9</mu1>
      <mu2>0.9</mu2>
    </gazebo>

    <gazebo reference="${name}_joint">
       <implicitSpringDamper>1</implicitSpringDamper>
    </gazebo>
  </xacro:macro>

  <!--************************-->
  <!--      HEAD_2 (TILT)     -->
  <!--************************-->
  <xacro:macro name="reem_head_2" params="name parent">
    <link name="${name}_link">
      <inertial>
        <origin xyz="-0.023981 -0.100591 0.000294" rpy="0 0 0" />
        <mass value="0.920999" />
        <!-- NOTE: Assuming box with d=0.28433, w=0.20302, h=0.26741 -->
<!--         <inertia ixx="0.011353"  ixy="0"  ixz="0" iyy="0.012294" iyz="0" izz="0.015345" /> -->
        <!--NOTE: Low (0.1 or lower) diagonal inertia values make Gazebo 1.0.2 simulation unstable when head sensors are added.-->
        <inertia ixx="0.005972"  ixy="-0.000046"  ixz="0.000006" iyy="0.006327" iyz="0.000030" izz="0.006213" />
      </inertial>
      <visual>
        <origin rpy="0 0 0" xyz="0 0 0"/>
        <geometry>
          <mesh filename="package://reemc_description/meshes/head/head_2_v1.stl" />
        </geometry>
        <material name="LightGrey" />
      </visual>
      <collision>
        <origin xyz="-0.03 0 0" rpy="0 0 0" />
        <geometry>
          <mesh filename="package://reemc_description/meshes/head/head_2_collision.stl" />
        </geometry>
      </collision>
    </link>

    <joint name="${name}_joint" type="revolute">
      <parent link="${parent}"/>
        <child link="${name}_link"/>
      <origin xyz="0.0445 0 0" rpy="${-90.0 * deg_to_rad} ${0.0 * deg_to_rad}  0" />
      <axis xyz="0 0 1" />
      <limit lower="${-15.0 * deg_to_rad}" upper="${45.0 * deg_to_rad}" effort="3.26" velocity="${head_max_vel}" />
      <dynamics damping="${head_damping}" friction="${head_friction}"/>

      <safety_controller k_position="20"
                         k_velocity="20"
                         soft_lower_limit="${-13.0 * deg_to_rad + head_eps}"
                         soft_upper_limit="${ 43.0 * deg_to_rad}" />
    </joint>

    <gazebo reference="${name}_link">
      <mu1>0.9</mu1>
      <mu2>0.9</mu2>
    </gazebo>

    <gazebo reference="${name}_joint">
       <implicitSpringDamper>1</implicitSpringDamper>
    </gazebo>


    <!-- Head Sonar -->
    <xacro:range_reem name="head_sonar_03" parent="${name}" ros_topic="sonar_torso" update_rate="5" maxRange="0.6" minRange="0.0" fov="0.3491" radiation="ultrasound">
      <origin xyz="0.11 -0.195 0.0" rpy="1.57 0.0 0.0" />
    </xacro:range_reem>
  </xacro:macro>

  <xacro:macro name="reem_head" params="name parent">
    <xacro:reem_head_1 name="${name}_1" parent="${parent}" />
    <xacro:reem_head_2 name="${name}_2" parent="${name}_1_link"/>
    <xacro:head_transmission name="${name}"/>
  </xacro:macro>

</robot>
