<?xml version="1.0" ?>
<robot name="reemc" xmlns:controller="http://playerstage.sourceforge.net/gazebo/xmlschema/#controller" xmlns:interface="http://playerstage.sourceforge.net/gazebo/xmlschema/#interface" xmlns:sensor="http://playerstage.sourceforge.net/gazebo/xmlschema/#sensor" xmlns:xacro="http://www.ros.org/wiki/xacro">
<link name="pelvis">
    <inertial>
      <mass value="6.0"/>
      <origin rpy="0 0 0" xyz="0.0 0.0 0.0"/>
      <inertia ixx="0.11" ixy="0" ixz="0" iyy="0.2" iyz="0.0" izz="0.15"/>
    </inertial>
    <visual>
      <origin rpy="0 -0 0" xyz="0 0 0"/>
      <geometry>
        <box size="0.02 0.14 0.02"/>
      </geometry>
    </visual>
    <collision>
      <origin rpy="0 -0 0" xyz="0 0 0"/>
      <geometry>
        <box size="0.02 0.14 0.02"/>
      </geometry>
    </collision>
  </link>

<link name="l_hip_z_link">
    <inertial>
      <mass value="1.0"/>
      <origin rpy="0 0 0" xyz="0.0 0.0 0.0"/>
      <inertia ixx="0.1" ixy="0" ixz="0" iyy="0.1" iyz="0.0" izz="0.1"/>
    </inertial>
  </link>

<joint name="l_hip_z_joint" type="revolute">
    <origin rpy="0 0 0" xyz="0 -0.07 0"/>
    <axis xyz="0 0 1"/>
    <parent link="pelvis"/>
    <child link="l_hip_z_link"/>
    <dynamics damping="0.1" friction="0"/>
    <limit effort="124.016" lower="-1.5708" upper="1.5708" velocity="12"/>
    <safety_controller k_position="100" k_velocity="100" soft_lower_limit="-10.6109" soft_upper_limit="10.6109"/>
  </joint>

  <link name="l_hip_x_link">
    <inertial>
      <mass value="1.0"/>
      <origin rpy="0 0 0" xyz="0.0 0.0 0.0"/>
      <inertia ixx="0.1" ixy="0" ixz="0" iyy="0.1" iyz="0.0" izz="0.1"/>
    </inertial>
  </link>

  <joint name="l_hip_x_joint" type="revolute">
    <origin xyz="0 0 0.0" rpy="0 1.5708 0" />
    <axis xyz="0 0 1"/>
    <parent link="l_hip_z_link"/>
    <child link="l_hip_x_link"/>
    <dynamics damping="0.1" friction="0"/>
       <limit effort="124.016" lower="-1.5708" upper="1.5708" velocity="12"/>
    <safety_controller k_position="100" k_velocity="100" soft_lower_limit="-10.6109" soft_upper_limit="10.6109"/>
  </joint>

<link name="l_hip_y_link">
    <inertial>
      <mass value="2.0"/>
      <origin rpy="0 0 0" xyz="0.0 0.0 0.0"/>
      <inertia ixx="0.1" ixy="0" ixz="0" iyy="0.1" iyz="0.0" izz="0.1"/>
    </inertial>
     <visual>
      <origin rpy="0 1.5708 0" xyz="0.175 0 0.0"/>
      <geometry>
        <cylinder length="0.35" radius="0.025"/>
      </geometry>
    </visual>
    <collision>
      <origin rpy="0 1.5708 0" xyz="0.175 0 0.0"/>
      <geometry>
        <cylinder length="0.35" radius="0.025"/>
      </geometry>
    </collision>
  </link>

  <joint name="l_hip_y_joint" type="revolute">
    <origin xyz="0 0 0.0" rpy="1.5708 0 0" />
    <axis xyz="0 0 1"/>
    <parent link="l_hip_x_link"/>
    <child link="l_hip_y_link"/>
    <dynamics damping="0.1" friction="0"/>
    <limit effort="124.016" lower="-1.5708" upper="1.5708" velocity="12"/>
    <safety_controller k_position="100" k_velocity="100" soft_lower_limit="-10.6109" soft_upper_limit="10.6109"/>
  </joint>

  <link name="l_knee_link">
    <inertial>
      <mass value="2.0"/>
      <origin rpy="0 0 0" xyz="0.0 0.0 0.0"/>
      <inertia ixx="0.1" ixy="0" ixz="0" iyy="0.1" iyz="0.0" izz="0.1"/>
    </inertial>
   <visual>
      <origin rpy="0 1.5708 0" xyz="0.175 0 0.0"/>
      <geometry>
        <cylinder length="0.35" radius="0.025"/>
      </geometry>
    </visual>
    <collision>
      <origin rpy="0 1.5708 0" xyz="0.175 0 0"/>
      <geometry>
        <cylinder length="0.35" radius="0.025"/>
      </geometry>
    </collision>
  </link>

  <joint name="l_knee_joint" type="revolute">
    <origin xyz="0.35 0 0.0" rpy="0 0 0" />
    <axis xyz="0 0 1"/>
    <parent link="l_hip_y_link"/>
    <child link="l_knee_link"/>
    <dynamics damping="0.1" friction="0"/>
    <limit effort="124.016" lower="-1.5708" upper="1.5708" velocity="12"/>
    <safety_controller k_position="100" k_velocity="100" soft_lower_limit="-10.6109" soft_upper_limit="10.6109"/>
  </joint>

  <link name="l_ankle_y_link">
    <inertial>
      <mass value="1.0"/>
      <origin rpy="0 0 0" xyz="0.0 0.0 0.0"/>
      <inertia ixx="0.1" ixy="0" ixz="0" iyy="0.1" iyz="0.0" izz="0.1"/>
    </inertial>
  </link>

  <joint name="l_ankle_y_joint" type="revolute">
    <origin xyz="0.35 0 0.0" rpy="0 0 0" />
    <axis xyz="0 0 1"/>
    <parent link="l_knee_link"/>
    <child link="l_ankle_y_link"/>
    <dynamics damping="0.1" friction="0"/>
    <limit effort="124.016" lower="-1.5708" upper="1.5708" velocity="12"/>
    <safety_controller k_position="100" k_velocity="100" soft_lower_limit="-10.6109" soft_upper_limit="10.6109"/>
  </joint>

  <link name="l_ankle_x_link">
    <inertial>
      <mass value="1.0"/>
      <origin rpy="0 0 0" xyz="0.0 0.0 0.0"/>
      <inertia ixx="0.01" ixy="0" ixz="0" iyy="0.01" iyz="0.0" izz="0.01"/>
    </inertial>
    <visual>
      <origin rpy="0 0 0" xyz="0.0 0 0.05"/>
      <geometry>
        <box size="0.02 0.08 0.16"/>
      </geometry>
    </visual>
    <collision>
      <origin rpy="0 0 0" xyz="0.0 0 0.05"/>
      <geometry>
        <box size="0.02 0.08 0.16"/>
      </geometry>
    </collision>
  </link>

  <joint name="l_ankle_x_joint" type="revolute">
    <origin xyz="0.0 0 0.0" rpy="-1.5708 0 0" />
    <axis xyz="0 0 1"/>
    <parent link="l_ankle_y_link"/>
    <child link="l_ankle_x_link"/>
    <dynamics damping="0.1" friction="0"/>
    <limit effort="124.016" lower="-1.5708" upper="1.5708" velocity="12"/>
    <safety_controller k_position="100" k_velocity="100" soft_lower_limit="-10.6109" soft_upper_limit="10.6109"/>
  </joint>



  <link name="r_hip_z_link">
    <inertial>
      <mass value="1.0"/>
      <origin rpy="0 0 0" xyz="0.0 0.0 0.0"/>
      <inertia ixx="0.1" ixy="0" ixz="0" iyy="0.1" iyz="0.0" izz="0.1"/>
    </inertial>
  </link>

<joint name="r_hip_z_joint" type="revolute">
    <origin rpy="0 0 0" xyz="0 0.07 0"/>
    <axis xyz="0 0 1"/>
    <parent link="pelvis"/>
    <child link="r_hip_z_link"/>
    <dynamics damping="0.1" friction="0"/>
    <limit effort="124.016" lower="-1.5708" upper="1.5708" velocity="12"/>
    <safety_controller k_position="100" k_velocity="100" soft_lower_limit="-10.6109" soft_upper_limit="10.6109"/>
  </joint>

  <link name="r_hip_x_link">
    <inertial>
      <mass value="1.0"/>
      <origin rpy="0 0 0" xyz="0.0 0.0 0.0"/>
      <inertia ixx="0.1" ixy="0" ixz="0" iyy="0.1" iyz="0.0" izz="0.1"/>
    </inertial>
  </link>

  <joint name="r_hip_x_joint" type="revolute">
    <origin xyz="0 0 0.0" rpy="0 1.5708 0" />
    <axis xyz="0 0 1"/>
    <parent link="r_hip_z_link"/>
    <child link="r_hip_x_link"/>
    <dynamics damping="0.1" friction="0"/>
    <limit effort="124.016" lower="-1.5708" upper="1.5708" velocity="12"/>
    <safety_controller k_position="100" k_velocity="100" soft_lower_limit="-10.6109" soft_upper_limit="10.6109"/>
  </joint>

<link name="r_hip_y_link">
    <inertial>
      <mass value="2.0"/>
      <origin rpy="0 0 0" xyz="0.0 0.0 0.0"/>
      <inertia ixx="0.1" ixy="0" ixz="0" iyy="0.1" iyz="0.0" izz="0.1"/>
    </inertial>
    <visual>
      <origin rpy="0 1.5708 0" xyz="0.175 0 0.0"/>
      <geometry>
        <cylinder length="0.35" radius="0.025"/>
      </geometry>
    </visual>
    <collision>
      <origin rpy="0 1.5708 0" xyz="0.175 0 0"/>
      <geometry>
        <cylinder length="0.35" radius="0.025"/>
      </geometry>
    </collision>
  </link>

  <joint name="r_hip_y_joint" type="revolute">
    <origin xyz="0 0 0.0" rpy="1.5708 0 0" />
    <axis xyz="0 0 1"/>
    <parent link="r_hip_x_link"/>
    <child link="r_hip_y_link"/>
    <dynamics damping="0.1" friction="0"/>
    <limit effort="124.016" lower="-1.5708" upper="1.5708" velocity="12"/>
    <safety_controller k_position="100" k_velocity="100" soft_lower_limit="-10.6109" soft_upper_limit="10.6109"/>
  </joint>

  <link name="r_knee_link">
    <inertial>
      <mass value="2.0"/>
      <origin rpy="0 0 0" xyz="0.0 0.0 0.0"/>
      <inertia ixx="0.1" ixy="0" ixz="0" iyy="0.1" iyz="0.0" izz="0.1"/>
    </inertial>
    <visual>
      <origin rpy="0 1.5708 0" xyz="0.175 0 0.0"/>
      <geometry>
        <cylinder length="0.35" radius="0.025"/>
      </geometry>
    </visual>
    <collision>
      <origin rpy="0 1.5708 0" xyz="0.175 0 0"/>
      <geometry>
        <cylinder length="0.35" radius="0.025"/>
      </geometry>
    </collision>
  </link>

  <joint name="r_knee_joint" type="revolute">
    <origin xyz="0.35 0 0.0" rpy="0 0 0" />
    <axis xyz="0 0 1"/>
    <parent link="r_hip_y_link"/>
    <child link="r_knee_link"/>
    <dynamics damping="0.1" friction="0"/>
    <limit effort="124.016" lower="-1.5708" upper="1.5708" velocity="12"/>
    <safety_controller k_position="100" k_velocity="100" soft_lower_limit="-10.6109" soft_upper_limit="10.6109"/>
  </joint>

  <link name="r_ankle_y_link">
    <inertial>
      <mass value="1.0"/>
      <origin rpy="0 0 0" xyz="0.0 0.0 0.0"/>
      <inertia ixx="0.1" ixy="0" ixz="0" iyy="0.1" iyz="0.0" izz="0.1"/>
    </inertial>
  </link>

  <joint name="r_ankle_y_joint" type="revolute">
    <origin xyz="0.35 0 0.0" rpy="0 0 0" />
    <axis xyz="0 0 1"/>
    <parent link="r_knee_link"/>
    <child link="r_ankle_y_link"/>
    <dynamics damping="0.1" friction="0"/>
    <limit effort="124.016" lower="-1.5708" upper="1.5708" velocity="12"/>
    <safety_controller k_position="100" k_velocity="100" soft_lower_limit="-10.6109" soft_upper_limit="10.6109"/>
  </joint>

  <link name="r_ankle_x_link">
    <inertial>
      <mass value="1.0"/>
      <origin rpy="0 0 0" xyz="0.0 0.0 0.0"/>
      <inertia ixx="0.01" ixy="0" ixz="0" iyy="0.01" iyz="0.0" izz="0.01"/>
    </inertial>
    <visual>
      <origin rpy="0 0 0" xyz="0.0 0 0.05"/>
      <geometry>
        <box size="0.02 0.08 0.16"/>
      </geometry>
    </visual>
    <collision>
      <origin rpy="0 0 0" xyz="0.0 0 0.05"/>
      <geometry>
        <box size="0.02 0.08 0.16"/>
      </geometry>
    </collision>
  </link>

  <joint name="r_ankle_x_joint" type="revolute">
    <origin xyz="0.0 0 0.0" rpy="-1.5708 0 0" />
    <axis xyz="0 0 1"/>
    <parent link="r_ankle_y_link"/>
    <child link="r_ankle_x_link"/>
    <dynamics damping="0.1" friction="0"/>
    <limit effort="124.016" lower="-1.5708" upper="1.5708" velocity="12"/>
    <safety_controller k_position="100" k_velocity="100" soft_lower_limit="-10.6109" soft_upper_limit="10.6109"/>
  </joint>
  <gazebo>
    <!-- robot model offset -->
    <pose>0 0 0.93 0 0 0</pose>
  </gazebo>
  <gazebo>
    <plugin filename="libgazebo_ros_joint_trajectory.so" name="joint_trajectory_plugin">
      <topicName>joint_trajectory</topicName>
      <updateRate>1000.0</updateRate>
    </plugin>
    <plugin filename="libgazebo_ros_controller_manager.so" name="gazebo_ros_controller_manager">
      <alwaysOn>true</alwaysOn>
      <updateRate>1000.0</updateRate>
    </plugin>
  </gazebo>
  <gazebo>
    <plugin filename="libgazebo_ros_p3d.so" name="gazebo_ros_p3d">
      <bodyName>pelvis</bodyName>
      <topicName>/ground_truth_odom</topicName>
      <alwaysOn>true</alwaysOn>
      <updateRate>100.0</updateRate>
    </plugin>
  </gazebo>

</robot>
