<?xml version="1.0"?>
<!--

  Copyright (c) 2011-2012, PAL Robotics, S.L.
  All rights reserved.

  This work is licensed under the Creative Commons Attribution-NonCommercial-NoDerivs 3.0 Unported License.
  To view a copy of this license, visit http://creativecommons.org/licenses/by-nc-nd/3.0/ or send a letter to
  Creative Commons, 444 Castro Street, Suite 900, Mountain View, California, 94041, USA.
-->
<robot name="reemc" xmlns:xacro="http://ros.org/wiki/xacro">

  <!--File includes-->
  <xacro:include filename="$(find reemc_description)/urdf/deg_to_rad.xacro" />
  <xacro:include filename="$(find reemc_description)/urdf/leg/leg.transmission.xacro" />
  <xacro:include filename="$(find reemc_description)/urdf/sensors/ftsensor.gazebo.xacro"/>
  <xacro:include filename="$(find reemc_description)/urdf/sensors/laser.urdf.xacro"/>

  <!--Constant parameters-->
  <xacro:property name="leg_friction"       value="1.0" />
  <xacro:property name="leg_damping"        value="1.0" />
  <xacro:property name="leg_reduction"      value="1.0" />
  <xacro:property name="leg_eps"            value="0.0" />

  <xacro:property name="leg_1_joint_max_vel"        value="2.35" />
  <xacro:property name="leg_2_joint_max_vel"        value="2.27" />
  <xacro:property name="leg_3_joint_max_vel"        value="3.64" />
  <xacro:property name="leg_4_joint_max_vel"        value="3.225" />
  <xacro:property name="leg_5_joint_max_vel"        value="2.44" />
  <xacro:property name="leg_6_joint_max_vel"        value="2.27" />

  <xacro:property name="leg_1_joint_effort"        value="42.7" />
  <xacro:property name="leg_2_joint_effort"        value="64.0" />
  <xacro:property name="leg_3_joint_effort"        value="55.7" />
  <xacro:property name="leg_4_joint_effort"        value="138.3" />
  <xacro:property name="leg_5_joint_effort"        value="80.9" />
  <xacro:property name="leg_6_joint_effort"        value="64.0" />


  <xacro:macro name="reemc_leg" params="name parent side reflect">

    <link name="leg_${side}_1_link">
        <inertial>
          <mass value="1.02901"/>
          <origin xyz="-0.02571 0 0.02557" rpy="0 0 0"/>
          <inertia ixx="0.00132187534" ixy="0.00000001514" ixz="0.00040022268" iyy="0.0018528617" iyz="0.00000050713" izz="0.00084231334"/>
        </inertial>
        <visual>
        <origin rpy="0 0 0" xyz="0 0 0"/>
        <geometry>
          <mesh filename="package://reemc_description/meshes/leg/leg_1.dae" scale="1 1 1"/>
        </geometry>
        <material name="LightGrey" />
      </visual>
      </link>

    <joint name="leg_${side}_1_joint" type="revolute">
        <origin  xyz="0  ${-reflect*0.075} -0.14353" rpy="0 0 0"/>
        <axis xyz="0 0 1"/>
        <parent link="${parent}"/>
        <child link="leg_${side}_1_link"/>
        <dynamics friction="${leg_friction}" damping="${leg_damping}"/>
        <limit lower="${-37.5*deg_to_rad + reflect*7.5*deg_to_rad}" upper="${37.5*deg_to_rad + reflect*7.5*deg_to_rad}" effort="${leg_1_joint_effort}" velocity="${leg_1_joint_max_vel}" />
 
        <safety_controller k_position="100"
                           k_velocity="100"
                           soft_lower_limit="${-37.5*deg_to_rad + reflect*7.5*deg_to_rad + leg_eps}"
                           soft_upper_limit="${ 37.5*deg_to_rad + reflect*7.5*deg_to_rad - leg_eps}" />
      </joint>

      <link name="leg_${side}_2_link">
        <inertial>
          <mass value="0.69621"/>
          <origin xyz="0.00057	${-reflect*0.00881}	-0.01125" rpy="0.0 0.0 0.0"/>
          <inertia ixx="0.0008416476" ixy="-0.00000268743" ixz="0.00000667199" iyy="0.00039794844" iyz="0.00002668971" izz="0.00084196694"/>
        </inertial>
        <visual>
          <origin rpy="${90*deg_to_rad} 0 0" xyz="0 0 0"/>
          <geometry>
            <cylinder length="0.10" radius="0.04"/>
          </geometry>
          <material name="LightGrey" />
        </visual>
      </link>

      <joint name="leg_${side}_2_joint" type="revolute">
        <origin xyz="0 0 0.0" rpy="0 ${ 90.0 * deg_to_rad} 0" />
        <axis xyz="0 0 1"/>
        <parent link="leg_${side}_1_link"/>
        <child link="leg_${side}_2_link"/>
        <dynamics friction="${leg_friction}" damping="${leg_damping}"/>
        <limit lower="${-22.5*deg_to_rad - reflect*7.5*deg_to_rad}" upper="${22.5*deg_to_rad - reflect*7.5*deg_to_rad}" effort="${leg_2_joint_effort}" velocity="${leg_2_joint_max_vel}" />

        <safety_controller k_position="100"
                           k_velocity="100"
                           soft_lower_limit="${-22.5*deg_to_rad - reflect*7.5*deg_to_rad + leg_eps}"
                           soft_upper_limit="${ 22.5*deg_to_rad - reflect*7.5*deg_to_rad - leg_eps}" />
    </joint>

    <link name="leg_${side}_3_link">
      <inertial>
        <mass value="3.97852"/>
        <origin xyz="0.14784 -0.01646 ${-reflect*0.01793}" rpy="0.0 0 0.0"/>
        <inertia ixx="0.00507885174" ixy="-0.00034076421" ixz="-0.00225952731" iyy="0.02850097402" iyz="0.00003047874" izz="0.02632392239"/>
      </inertial>
     <visual>
        <origin rpy="0 0 0" xyz="0 0 0"/>
        <geometry>
          <mesh filename="package://reemc_description/meshes/leg/leg_3.dae" scale="1 1 ${-1*reflect}"/>
        </geometry>
        <material name="LightGrey" />
      </visual>
      <collision>
        <origin rpy="0 ${90* deg_to_rad} 0" xyz="0.15 0 ${-reflect*0.015}"/>
        <geometry>
          <box size="0.15 0.10 0.20"/>
        </geometry>
      </collision>
    </link>

    <joint name="leg_${side}_3_joint" type="revolute">
      <origin xyz="0 0 0.0" rpy="${ -90.0 * deg_to_rad} 0 0" />
      <axis xyz="0 0 1"/>
      <parent link="leg_${side}_2_link"/>
      <child link="leg_${side}_3_link"/>
      <dynamics friction="${leg_friction}" damping="${leg_damping}"/>
      <limit lower="${ -100.0 * deg_to_rad}" upper="${45 * deg_to_rad}" effort="${leg_3_joint_effort}" velocity="${leg_3_joint_max_vel}" />

      <safety_controller k_position="100"
                         k_velocity="100"
                         soft_lower_limit="${-100.0 * deg_to_rad + leg_eps}"
                         soft_upper_limit="${  45.0 * deg_to_rad - leg_eps}" />
    </joint>

    <link name="leg_${side}_4_link">
      <inertial>
        <mass value="2.86055"/>
        <origin xyz="0.14618 -0.0022 ${-reflect*0.02189}" rpy="0.0 0.0 0.0"/>
        <inertia ixx="0.00361006492" ixy="0.00012218208" ixz="0.00160208242" iyy="0.02470649045" iyz="0.00008129755" izz="0.02272322206"/>
      </inertial>
      <visual>
        <origin rpy="0 0 0" xyz="0 0 0"/>
        <geometry>
          <mesh filename="package://reemc_description/meshes/leg/leg_4.dae" scale="1 1 ${-1*reflect}"/>
        </geometry>
        <material name="LightGrey" />
      </visual>
      <collision>
        <origin rpy="0 ${-reflect* 90* deg_to_rad} 0" xyz="0.15 0 ${-reflect*0.015}"/>
        <geometry>
          <box size="0.15 0.10 0.20"/>
        </geometry>
      </collision>
    </link>

    <joint name="leg_${side}_4_joint" type="revolute">
      <origin xyz="0.300 0 0.0" rpy="0 0 0" />
      <axis xyz="0 0 1"/>
      <parent link="leg_${side}_3_link"/>
      <child link="leg_${side}_4_link"/>
      <dynamics damping="0.1" friction="0"/>
      <dynamics friction="${leg_friction}" damping="${leg_damping}"/>
      <limit lower="${0 * deg_to_rad}" upper="${ 150.0 * deg_to_rad}" effort="${leg_4_joint_effort}" velocity="${leg_4_joint_max_vel}" />

      <safety_controller k_position="100"
                         k_velocity="100"
                         soft_lower_limit="${  0.0 * deg_to_rad + leg_eps}"
                         soft_upper_limit="${150.0 * deg_to_rad - leg_eps}" />
    </joint>

    <link name="leg_${side}_5_link">
      <inertial>
        <mass value="0.68213"/>
        <origin xyz="-0.00028	0.01119	${-reflect*0.00859}" rpy="0.0 0.0 0.0"/>
        <inertia ixx="0.00082035023" ixy="0.00000048534" ixz="0.00000226301" iyy="0.00082074105" iyz="-0.00002892247" izz="0.00037614067"/>
      </inertial>
      <visual>
        <origin rpy="0 0 0" xyz="0 0 0"/>
        <geometry>
          <cylinder length="0.104" radius="0.04"/>
        </geometry>
        <material name="LightGrey" />
      </visual>

    </link>

    <joint name="leg_${side}_5_joint" type="revolute">
      <origin xyz="0.30 0 0.0" rpy="0 0 0" />
      <axis xyz="0 0 1"/>
      <parent link="leg_${side}_4_link"/>
      <child link="leg_${side}_5_link"/>
      <dynamics friction="${leg_friction}" damping="${leg_damping}"/>
      <limit lower="${-75 * deg_to_rad}" upper="${ 45.0 * deg_to_rad}" effort="${leg_5_joint_effort}" velocity="${leg_5_joint_max_vel}" />

      <safety_controller k_position="100"
                         k_velocity="100"
                         soft_lower_limit="${ -75.0 * deg_to_rad + leg_eps}"
                         soft_upper_limit="${  45.0 * deg_to_rad - leg_eps}" />
    </joint>

    <link name="leg_${side}_6_link">
      <inertial>
        <mass value="2.00843"/>
        <origin xyz="0.06111 ${-reflect*0.00336} -0.00497" rpy="0.0 0.0 0.0"/>
        <inertia ixx="0.00366502559" ixy="0.00020479295" ixz="0.00112439297" iyy="0.00532618026" iyz="0.00012133755" izz="0.00353091463"/>
      </inertial>
      <visual>
        <origin rpy="0 0 0" xyz="0 0 0"/>
        <geometry>
          <mesh filename="package://reemc_description/meshes/leg/leg_6.dae" scale="1 ${-1*reflect} 1"/>
        </geometry>
        <material name="LightGrey" />
      </visual>
      <collision>
        <origin rpy="0 0 0" xyz="0.1 ${-reflect*0.01} 0.025 "/>
        <geometry>
          <box size="0.02 0.14 0.210"/>
        </geometry>
      </collision>
    </link>

    <joint name="leg_${side}_6_joint" type="revolute">
      <origin xyz="0 0 0" rpy="${90.0 * deg_to_rad} 0 0" />
      <axis xyz="0 0 1"/>
      <parent link="leg_${side}_5_link"/>
      <child link="leg_${side}_6_link"/>
      <dynamics friction="${leg_friction}" damping="${leg_damping}"/>
      <limit lower="${-22.5*deg_to_rad + reflect*7.5*deg_to_rad}" upper="${ 22.5*deg_to_rad + reflect*7.5*deg_to_rad}" effort="${leg_6_joint_effort}" velocity="${leg_6_joint_max_vel}" />

      <safety_controller k_position="100"
                         k_velocity="100"
                         soft_lower_limit="${-22.5*deg_to_rad + reflect*7.5*deg_to_rad + leg_eps}"
                         soft_upper_limit="${ 22.5*deg_to_rad + reflect*7.5*deg_to_rad - leg_eps}" />
    </joint>

    <link name="${side}_sole_link">
      <inertial>
        <mass value="0.001"/>
        <origin xyz="0 0 0" rpy="0 0 0"/>
        <inertia ixx="0.0" ixy="0.0" ixz="0.0" iyy="0.0" iyz="0.0" izz="0.0"/>
      </inertial>
    </link>

    <joint name="${side}_sole_joint" type="fixed">
      <!-- origin x taken from link_${side}_6_link/visual/origin/x above -->
      <origin xyz="0.117 0.0 0.0" rpy="0.0 ${-90.0 * deg_to_rad} 0.0"/>
      <axis xyz="0 0 1"/>
      <parent link="leg_${side}_6_link"/>
      <child link="${side}_sole_link"/>
      <dynamics friction="${leg_friction}" damping="${leg_damping}"/>
      <limit lower="0.0" upper="0.0" effort="60" velocity="0"/>
    </joint>


   <gazebo reference="leg_${side}_1_link">
     <mu1>0.9</mu1>
     <mu2>0.9</mu2>
   </gazebo>
   <gazebo reference="leg_${side}_2_link">
     <mu1>0.9</mu1>
     <mu2>0.9</mu2>
   </gazebo>
   <gazebo reference="leg_${side}_3_link">
     <mu1>0.9</mu1>
     <mu2>0.9</mu2>
   </gazebo>
   <gazebo reference="leg_${side}_4_link">
     <mu1>0.9</mu1>
     <mu2>0.9</mu2>
   </gazebo>
   <gazebo reference="leg_${side}_5_link">
     <mu1>0.9</mu1>
     <mu2>0.9</mu2>
   </gazebo>

   <!-- contact model for foot surface -->
   <gazebo reference="leg_${side}_6_link">
     <kp>1000000.0</kp>
     <kd>100.0</kd>
     <mu1>1.0</mu1>
     <mu2>1.0</mu2>
     <fdir1>0 0 1</fdir1>
     <maxVel>1.0</maxVel>
     <minDepth>0.00</minDepth>
     <implicitSpringDamper>1</implicitSpringDamper>
   </gazebo>

   <!--force torque sensor -->
   <!--xacro:reemc_force_torque_sensor name="leg_${side}_6_link"  update_rate="100.0"/-->

   <gazebo reference="leg_${side}_1_joint">
      <implicitSpringDamper>1</implicitSpringDamper>
   </gazebo>
   <gazebo reference="leg_${side}_2_joint">
      <implicitSpringDamper>1</implicitSpringDamper>
   </gazebo>
   <gazebo reference="leg_${side}_3_joint">
      <implicitSpringDamper>1</implicitSpringDamper>
   </gazebo>
   <gazebo reference="leg_${side}_4_joint">
      <implicitSpringDamper>1</implicitSpringDamper>
   </gazebo>
   <gazebo reference="leg_${side}_5_joint">
      <implicitSpringDamper>1</implicitSpringDamper>
   </gazebo>
   <gazebo reference="leg_${side}_6_joint">
     <implicitSpringDamper>1</implicitSpringDamper>
     <provideFeedback>1</provideFeedback>
   </gazebo>

    <xacro:reemc_leg_simple_transmission name="${name}" side="${side}" number="1" reduction="${leg_reduction}" />
    <xacro:reemc_leg_simple_transmission name="${name}" side="${side}" number="2" reduction="${leg_reduction}" />
    <xacro:reemc_leg_simple_transmission name="${name}" side="${side}" number="3" reduction="${leg_reduction}" />
    <xacro:reemc_leg_simple_transmission name="${name}" side="${side}" number="4" reduction="${leg_reduction}" />
    <xacro:reemc_leg_simple_transmission name="${name}" side="${side}" number="5" reduction="${leg_reduction}" />
    <xacro:reemc_leg_simple_transmission name="${name}" side="${side}" number="6" reduction="${leg_reduction}" />

   <xacro:reemc_laser name="${side}_laser" parent="${side}_sole_link" ros_topic="${side}_scan" update_rate="10.0" min_angle="${-90*deg_to_rad}" max_angle="${90*deg_to_rad}" nrays="360" >
     <origin xyz="${0.170 -0.085} ${0.071 -((1+reflect)*0.01 + 0.061)} ${0.073}" rpy="0.0 0.0 ${-30.0*reflect*deg_to_rad}" />
    </xacro:reemc_laser>

  </xacro:macro>
</robot>
